Traceback (most recent call last):
  File "C:\Users\RyanJoung\OneDrive - Datapod Pty Ltd\Desktop\uc\mybook\my_book\venv\lib\site-packages\nbclient\client.py", line 627, in _async_poll_for_reply
    msg = await ensure_async(self.kc.shell_channel.get_msg(timeout=new_timeout))
  File "C:\Users\RyanJoung\OneDrive - Datapod Pty Ltd\Desktop\uc\mybook\my_book\venv\lib\site-packages\nbclient\util.py", line 89, in ensure_async
    result = await obj
  File "C:\Users\RyanJoung\OneDrive - Datapod Pty Ltd\Desktop\uc\mybook\my_book\venv\lib\site-packages\jupyter_client\channels.py", line 230, in get_msg
    raise Empty
_queue.Empty

During handling of the above exception, another exception occurred:

Traceback (most recent call last):
  File "C:\Users\RyanJoung\OneDrive - Datapod Pty Ltd\Desktop\uc\mybook\my_book\venv\lib\site-packages\jupyter_cache\executors\utils.py", line 51, in single_nb_execution
    executenb(
  File "C:\Users\RyanJoung\OneDrive - Datapod Pty Ltd\Desktop\uc\mybook\my_book\venv\lib\site-packages\nbclient\client.py", line 1117, in execute
    return NotebookClient(nb=nb, resources=resources, km=km, **kwargs).execute()
  File "C:\Users\RyanJoung\OneDrive - Datapod Pty Ltd\Desktop\uc\mybook\my_book\venv\lib\site-packages\nbclient\util.py", line 78, in wrapped
    return just_run(coro(*args, **kwargs))
  File "C:\Users\RyanJoung\OneDrive - Datapod Pty Ltd\Desktop\uc\mybook\my_book\venv\lib\site-packages\nbclient\util.py", line 57, in just_run
    return loop.run_until_complete(coro)
  File "C:\Users\RyanJoung\AppData\Local\Programs\Python\Python38\lib\asyncio\base_events.py", line 616, in run_until_complete
    return future.result()
  File "C:\Users\RyanJoung\OneDrive - Datapod Pty Ltd\Desktop\uc\mybook\my_book\venv\lib\site-packages\nbclient\client.py", line 558, in async_execute
    await self.async_execute_cell(
  File "C:\Users\RyanJoung\OneDrive - Datapod Pty Ltd\Desktop\uc\mybook\my_book\venv\lib\site-packages\nbclient\client.py", line 846, in async_execute_cell
    exec_reply = await self.task_poll_for_reply
  File "C:\Users\RyanJoung\OneDrive - Datapod Pty Ltd\Desktop\uc\mybook\my_book\venv\lib\site-packages\nbclient\client.py", line 651, in _async_poll_for_reply
    await self._async_handle_timeout(timeout, cell)
  File "C:\Users\RyanJoung\OneDrive - Datapod Pty Ltd\Desktop\uc\mybook\my_book\venv\lib\site-packages\nbclient\client.py", line 701, in _async_handle_timeout
    raise CellTimeoutError.error_from_timeout_and_cell(
nbclient.exceptions.CellTimeoutError: A cell timed out while it was being executed, after 30 seconds.
The message was: Cell execution timed out.
Here is a preview of the cell contents:
-------------------
['import pandas as pd', 'import numpy as np', 'from tensorflow.keras import regularizers', 'from tensorflow.keras.utils import to_categorical', 'from tensorflow.keras.models import Sequential']
...
["                       dtype={'protocol_type': str, 'service': str, 'flag': str, 'result': str})", "    train_and_test('keras_kdd', data)", "#     data = pd.read_csv('./dataset/kdd_prediction_NSL.csv', delimiter=',',", "#                        dtype={'protocol_type': str, 'service': str, 'flag': str, 'result': str})", "#     train_and_test('keras_nsl_kdd', data)"]
-------------------

